Workbook

Sheet Summary
A1: AWS cost report: S3, EC2, EBS, snapshots, AWS Backup, copy job and S3 replication
A2: us-east-1 list prices, in USD. Every number links to the detail sheets; change any rate on the Rates sheet and this page updates. 'Our stacks' prices each Terraform folder as deployed.
A4: Service | B4: Item | C4: Per hour (USD) | D4: Per day (USD) | E4: Per month (USD) | F4: One-time (USD) | G4: Detail sheet
A5: Our Terraform stacks, as the scripts deploy them
A6: EC2 stack | B6: ec2-01: Instance + 8 GiB root. No protection | C6: ='Our stacks'!J10 -> 0.016276712 | D6: ='Our stacks'!K10 -> 0.3906411 | E6: ='Our stacks'!L10 -> 11.882 | F6: ='Our stacks'!M10 -> 0 | G6: Our stacks
A7: EC2 stack | B7: ec2-02: Instance + encrypted 1 GiB data volume | C7: ='Our stacks'!J11 -> 0.016386301 | D7: ='Our stacks'!K11 -> 0.39327123 | E7: ='Our stacks'!L11 -> 11.962 | F7: ='Our stacks'!M11 -> 0 | G7: Our stacks
A8: EC2 stack | B8: ec2-03: + data volume + 1 EBS snapshot | C8: ='Our stacks'!J12 -> 0.016386301 | D8: ='Our stacks'!K12 -> 0.39327123 | E8: ='Our stacks'!L12 -> 11.962 | F8: ='Our stacks'!M12 -> 0 | G8: Our stacks
A9: EC2 stack | B9: ec2-04: + data volume + snapshot + AMI | C9: ='Our stacks'!J13 -> 0.016454795 | D9: ='Our stacks'!K13 -> 0.39491507 | E9: ='Our stacks'!L13 -> 12.012 | F9: ='Our stacks'!M13 -> 0 | G9: Our stacks
A10: EC2 stack | B10: ec2-05: + data volume + DLM (24 h, keep 1) | C10: ='Our stacks'!J14 -> 0.016454795 | D10: ='Our stacks'!K14 -> 0.39491507 | E10: ='Our stacks'!L14 -> 12.012 | F10: ='Our stacks'!M14 -> 0 | G10: Our stacks
A11: EC2 stack | B11: ec2-06: Instance backup, 1 vault, no copy, no lock | C11: ='Our stacks'!J15 -> 0.016345205 | D11: ='Our stacks'!K15 -> 0.39228493 | E11: ='Our stacks'!L15 -> 11.932 | F11: ='Our stacks'!M15 -> 0 | G11: Our stacks
A12: EC2 stack | B12: ec2-07: Instance backup + copy to DR vault (DR locked) | C12: ='Our stacks'!J16 -> 0.016413699 | D12: ='Our stacks'!K16 -> 0.39392877 | E12: ='Our stacks'!L16 -> 11.982 | F12: ='Our stacks'!M16 -> 0.02 | G12: Our stacks
A13: EC2 stack | B13: ec2-08: Instance backup + copy to DR vault (DR locked) | C13: ='Our stacks'!J17 -> 0.011413699 | D13: ='Our stacks'!K17 -> 0.27392877 | E13: ='Our stacks'!L17 -> 8.332 | F13: ='Our stacks'!M17 -> 0.02 | G13: Our stacks
A14: EC2 stack | B14: ec2-09: Data-volume backup + copy to DR vault (DR locked) | C14: ='Our stacks'!J18 -> 0.011386301 | D14: ='Our stacks'!K18 -> 0.27327123 | E14: ='Our stacks'!L18 -> 8.312 | F14: ='Our stacks'!M18 -> 0 | G14: Our stacks
A15: EC2 stack | B15: ec2-backup-dr: Instance + data volume backup + copy to DR (DR locked) | C15: ='Our stacks'!J19 -> 0.011523288 | D15: ='Our stacks'!K19 -> 0.2765589 | E15: ='Our stacks'!L19 -> 8.412 | F15: ='Our stacks'!M19 -> 0.02 | G15: Our stacks
A16: EC2 stacks | B16: All 10 EC2 folders at once | C16: ='Our stacks'!J20 -> 0.1490411 | D16: ='Our stacks'!K20 -> 3.5769863 | E16: ='Our stacks'!L20 -> 108.8 | F16: ='Our stacks'!M20 -> 0.06 | G16: Our stacks
A17: S3 stack | B17: s3-05: Versioned bucket + AWS Backup, 1 vault, no copy (per 1 GB of data) | C17: ='Our stacks'!J24 -> 0.0001 | D17: ='Our stacks'!K24 -> 0.0024 | E17: ='Our stacks'!L24 -> 0.073 | F17: ='Our stacks'!M24 -> 0 | G17: Our stacks
A18: S3 stack | B18: s3-06: Bucket + AWS Backup + copy to DR vault (no lock) (per 1 GB of data) | C18: ='Our stacks'!J25 -> 0.00016849315 | D18: ='Our stacks'!K25 -> 0.0040438356 | E18: ='Our stacks'!L25 -> 0.123 | F18: ='Our stacks'!M25 -> 0.02 | G18: Our stacks
A19: S3 stack | B19: s3-backup-dr: Bucket + AWS Backup + copy to DR (DR locked) (per 1 GB of data) | C19: ='Our stacks'!J26 -> 0.00016849315 | D19: ='Our stacks'!K26 -> 0.0040438356 | E19: ='Our stacks'!L26 -> 0.123 | F19: ='Our stacks'!M26 -> 0.02 | G19: Our stacks
A20: S3 bucket: creation and object storage (S3 Standard)
A21: S3 | B21: 1 KB object, storage | C21: =S3!D6 -> 3.0047273e-11 | D21: =S3!E6 -> 7.2113455e-10 | E21: =S3!F6 -> 2.1934509e-08 | G21: S3
A22: S3 | B22: 1 MB object, storage | C22: =S3!D8 -> 3.0768408e-08 | D22: =S3!E8 -> 7.3844178e-07 | E22: =S3!F8 -> 2.2460937e-05 | G22: S3
A23: S3 | B23: 1 GB object, storage | C23: =S3!D9 -> 3.1506849e-05 | D23: =S3!E9 -> 0.00075616438 | E23: =S3!F9 -> 0.023 | G23: S3
A24: S3 | B24: 1 PUT request (upload) | F24: =S3!D13 -> 5e-06 | G24: S3
A25: AWS Backup: backup storage (one recovery point; no per-job fee)
A26: AWS Backup | B26: S3 object 1 KB (billed as 128 KB) | C26: ='AWS Backup'!D6 -> 8.3609803e-09 | D26: ='AWS Backup'!E6 -> 2.0066353e-07 | E26: ='AWS Backup'!F6 -> 6.1035156e-06 | G26: AWS Backup
A27: AWS Backup | B27: S3 object 1 MB | C27: ='AWS Backup'!D7 -> 6.6887842e-08 | D27: ='AWS Backup'!E7 -> 1.6053082e-06 | E27: ='AWS Backup'!F7 -> 4.8828125e-05 | G27: AWS Backup
A28: AWS Backup | B28: S3 object 1 GB | C28: ='AWS Backup'!D8 -> 6.8493151e-05 | D28: ='AWS Backup'!E8 -> 0.0016438356 | E28: ='AWS Backup'!F8 -> 0.05 | G28: AWS Backup
A29: AWS Backup | B29: EC2 instance backup, 1 GB used | C29: ='AWS Backup'!D9 -> 6.8493151e-05 | D29: ='AWS Backup'!E9 -> 0.0016438356 | E29: ='AWS Backup'!F9 -> 0.05 | G29: AWS Backup
A30: AWS Backup | B30: EBS data volume backup, empty (ec2-09) | C30: ='AWS Backup'!D11 -> 0 | D30: ='AWS Backup'!E11 -> 0 | E30: ='AWS Backup'!F11 -> 0 | G30: AWS Backup
A31: AWS Backup: copy job to a second region (transfer once + destination storage)
A32: Copy job | B32: EC2 1 GB copy | C32: ='AWS Backup'!F15 -> 6.8493151e-05 | D32: ='AWS Backup'!G15 -> 0.0016438356 | E32: ='AWS Backup'!H15 -> 0.05 | F32: ='AWS Backup'!E15 -> 0.02 | G32: AWS Backup
A33: Copy job | B33: EC2 8 GB copy | C33: ='AWS Backup'!F16 -> 0.00054794521 | D33: ='AWS Backup'!G16 -> 0.013150685 | E33: ='AWS Backup'!H16 -> 0.4 | F33: ='AWS Backup'!E16 -> 0.16 | G33: AWS Backup
A34: Copy job | B34: S3 1 MB copy | C34: ='AWS Backup'!F18 -> 6.6887842e-08 | D34: ='AWS Backup'!G18 -> 1.6053082e-06 | E34: ='AWS Backup'!H18 -> 4.8828125e-05 | F34: ='AWS Backup'!E18 -> 1.953125e-05 | G34: AWS Backup
A35: Copy job | B35: S3 1 GB copy | C35: ='AWS Backup'!F19 -> 6.8493151e-05 | D35: ='AWS Backup'!G19 -> 0.0016438356 | E35: ='AWS Backup'!H19 -> 0.05 | F35: ='AWS Backup'!E19 -> 0.02 | G35: AWS Backup
A36: Restore | B36: S3 restore, 1 GB | F36: ='AWS Backup'!D24 -> 0.02 | G36: AWS Backup
A37: S3 CRR: cross-region replication (replica storage + one-time replication)
A38: S3 CRR | B38: 1 KB object replicated | C38: ='S3 CRR'!D14 -> 3.0047273e-11 | D38: ='S3 CRR'!E14 -> 7.2113455e-10 | E38: ='S3 CRR'!F14 -> 2.1934509e-08 | F38: ='S3 CRR'!F6 -> 5.4190735e-06 | G38: S3 CRR
A39: S3 CRR | B39: 125.2 KB object replicated (your test) | C39: ='S3 CRR'!D15 -> 3.7619186e-09 | D39: ='S3 CRR'!E15 -> 9.0286046e-08 | E39: ='S3 CRR'!F15 -> 2.7462006e-06 | F39: ='S3 CRR'!F7 -> 7.7880005e-06 | G39: S3 CRR
A40: S3 CRR | B40: 1 MB object replicated | C40: ='S3 CRR'!D16 -> 3.0768408e-08 | D40: ='S3 CRR'!E16 -> 7.3844178e-07 | E40: ='S3 CRR'!F16 -> 2.2460937e-05 | F40: ='S3 CRR'!F8 -> 2.493125e-05 | G40: S3 CRR
A41: S3 CRR | B41: 1 GB object replicated | C41: ='S3 CRR'!D17 -> 3.1506849e-05 | D41: ='S3 CRR'!E17 -> 0.00075616438 | E41: ='S3 CRR'!F17 -> 0.023 | F41: ='S3 CRR'!F9 -> 0.0200054 | G41: S3 CRR
...

Sheet Folder costs
A1: Cost per folder
A2: Every Terraform folder as deployed, us-east-1 list prices in USD. EC2 rows link to the 'Our stacks' sheet; S3 rows use the Rates sheet and the bucket size in 'Our stacks'!C6. One-time costs (first cross-region copy) are on the 'Our stacks' sheet.
A4: A. EC2 folders (ec2/): every instance is left running
A5: Folder | B5: What it creates | C5: Per hour (USD) | D5: If stopped, per hour (USD) | E5: Per month (USD)
A6: ='Our stacks'!A10 -> ec2-01 | B6: ='Our stacks'!B10 -> Instance + 8 GiB root. No protection | C6: ='Our stacks'!J10 -> 0.016276712 | D6: ='Our stacks'!O10 -> 0.00087671233 | E6: ='Our stacks'!L10 -> 11.882
A7: ='Our stacks'!A11 -> ec2-02 | B7: ='Our stacks'!B11 -> Instance + encrypted 1 GiB data volume | C7: ='Our stacks'!J11 -> 0.016386301 | D7: ='Our stacks'!O11 -> 0.00098630137 | E7: ='Our stacks'!L11 -> 11.962
A8: ='Our stacks'!A12 -> ec2-03 | B8: ='Our stacks'!B12 -> + data volume + 1 EBS snapshot | C8: ='Our stacks'!J12 -> 0.016386301 | D8: ='Our stacks'!O12 -> 0.00098630137 | E8: ='Our stacks'!L12 -> 11.962
A9: ='Our stacks'!A13 -> ec2-04 | B9: ='Our stacks'!B13 -> + data volume + snapshot + AMI | C9: ='Our stacks'!J13 -> 0.016454795 | D9: ='Our stacks'!O13 -> 0.0010547945 | E9: ='Our stacks'!L13 -> 12.012
A10: ='Our stacks'!A14 -> ec2-05 | B10: ='Our stacks'!B14 -> + data volume + DLM (24 h, keep 1) | C10: ='Our stacks'!J14 -> 0.016454795 | D10: ='Our stacks'!O14 -> 0.0010547945 | E10: ='Our stacks'!L14 -> 12.012
A11: ='Our stacks'!A15 -> ec2-06 | B11: ='Our stacks'!B15 -> Instance backup, 1 vault, no copy, no lock | C11: ='Our stacks'!J15 -> 0.016345205 | D11: ='Our stacks'!O15 -> 0.00094520548 | E11: ='Our stacks'!L15 -> 11.932
A12: ='Our stacks'!A16 -> ec2-07 | B12: ='Our stacks'!B16 -> Instance backup + copy to DR vault (DR locked) | C12: ='Our stacks'!J16 -> 0.016413699 | D12: ='Our stacks'!O16 -> 0.0010136986 | E12: ='Our stacks'!L16 -> 11.982
A13: ='Our stacks'!A17 -> ec2-08 | B13: ='Our stacks'!B17 -> Instance backup + copy to DR vault (DR locked) | C13: ='Our stacks'!J17 -> 0.011413699 | D13: ='Our stacks'!O17 -> 0.0010136986 | E13: ='Our stacks'!L17 -> 8.332
A14: ='Our stacks'!A18 -> ec2-09 | B14: ='Our stacks'!B18 -> Data-volume backup + copy to DR vault (DR locked) | C14: ='Our stacks'!J18 -> 0.011386301 | D14: ='Our stacks'!O18 -> 0.00098630137 | E14: ='Our stacks'!L18 -> 8.312
A15: ='Our stacks'!A19 -> ec2-backup-dr | B15: ='Our stacks'!B19 -> Instance + data volume backup + copy to DR (DR locked) | C15: ='Our stacks'!J19 -> 0.011523288 | D15: ='Our stacks'!O19 -> 0.0011232877 | E15: ='Our stacks'!L19 -> 8.412
A16: All 10 EC2 folders | C16: =SUM(C6:C15) -> 0.1490411 | D16: =SUM(D6:D15) -> 0.010041096 | E16: =SUM(E6:E15) -> 108.8
A18: B. S3 folders (s3/): cost per GB of bucket data; an empty bucket costs $0
A19: Folder | B19: What it creates | C19: Per hour (USD) | D19: If empty, per hour (USD) | E19: Per month (USD) | F19: S3 copies of each GB | G19: Backup vault copies of each GB
A20: s3-01 | B20: Bare bucket, public access blocked | C20: =E20/Rates!$B$4 -> 3.1506849e-05 | D20: 0 | E20: ='Our stacks'!$C$6*(F20*Rates!$B$10+G20*Rates!$B$20) -> 0.023 | F20: 1 | G20: 0
A21: s3-02 | B21: Bucket + versioning | C21: =E21/Rates!$B$4 -> 3.1506849e-05 | D21: 0 | E21: ='Our stacks'!$C$6*(F21*Rates!$B$10+G21*Rates!$B$20) -> 0.023 | F21: 1 | G21: 0
A22: s3-03 | B22: Versioning + lifecycle rule + SSE-S3 encryption | C22: =E22/Rates!$B$4 -> 3.1506849e-05 | D22: 0 | E22: ='Our stacks'!$C$6*(F22*Rates!$B$10+G22*Rates!$B$20) -> 0.023 | F22: 1 | G22: 0
A23: s3-04 | B23: Cross-region replication (CRR) to us-west-2 | C23: =E23/Rates!$B$4 -> 6.3013699e-05 | D23: 0 | E23: ='Our stacks'!$C$6*(F23*Rates!$B$10+G23*Rates!$B$20) -> 0.046 | F23: 2 | G23: 0
A24: s3-05 | B24: AWS Backup, 1 vault, no copy, no lock | C24: =E24/Rates!$B$4 -> 0.0001 | D24: 0 | E24: ='Our stacks'!$C$6*(F24*Rates!$B$10+G24*Rates!$B$20) -> 0.073 | F24: 1 | G24: 1
A25: s3-06 | B25: AWS Backup + copy to DR vault (no lock) | C25: =E25/Rates!$B$4 -> 0.00016849315 | D25: 0 | E25: ='Our stacks'!$C$6*(F25*Rates!$B$10+G25*Rates!$B$20) -> 0.123 | F25: 1 | G25: 2
A26: s3-07 | B26: S3 Object Lock (governance) | C26: =E26/Rates!$B$4 -> 3.1506849e-05 | D26: 0 | E26: ='Our stacks'!$C$6*(F26*Rates!$B$10+G26*Rates!$B$20) -> 0.023 | F26: 1 | G26: 0
A27: s3-08 | B27: CRR + SRR + Object Lock (3 buckets) | C27: =E27/Rates!$B$4 -> 9.4520548e-05 | D27: 0 | E27: ='Our stacks'!$C$6*(F27*Rates!$B$10+G27*Rates!$B$20) -> 0.069 | F27: 3 | G27: 0
A28: s3-backup-dr | B28: AWS Backup + copy to DR vault (DR locked, compliance) | C28: =E28/Rates!$B$4 -> 0.00016849315 | D28: 0 | E28: ='Our stacks'!$C$6*(F28*Rates!$B$10+G28*Rates!$B$20) -> 0.123 | F28: 1 | G28: 2
A29: s3-replication | B29: CRR + SRR + Object Lock + SSE-S3 (3 buckets) | C29: =E29/Rates!$B$4 -> 9.4520548e-05 | D29: 0 | E29: ='Our stacks'!$C$6*(F29*Rates!$B$10+G29*Rates!$B$20) -> 0.069 | F29: 3 | G29: 0
A30: All 10 S3 folders | C30: =SUM(C20:C29) -> 0.00081506849 | D30: =SUM(D20:D29) -> 0 | E30: =SUM(E20:E29) -> 0.595
A31: Per month = bucket GB ('Our stacks'!C6, now 1 GB) x (S3 copies x S3 Standard rate + vault copies x AWS Backup rate). Not included: requests ($0.005 per 1,000 PUTs), the one-time $0.02/GB for CRR and cross-region backup copies, and old versions kept by versioning or Object Lock.

Sheet Our stacks
A1: Our Terraform stacks: cost of each folder as the scripts deploy it
A2: One row per folder in ec2/ and per AWS Backup folder in s3/. Quantities follow each main.tf; rates come from the Rates sheet. Per hour = compute + public IPv4 (while running) + EBS + snapshots + vault storage. One-time = the first cross-region copy, made by the first daily copy, or at apply in ec2-07 and ec2-09 (one on-demand backup job + one copy job). ec2-06, ec2-08 and ec2-backup-dr print the on-demand commands to run by hand. Every later daily copy sends only changed blocks.
A4: Root volume used data (GB) | C4: 1 | D4: Used data on the 8 GiB AL2023 root, so the size of its snapshot / backup. Set to 1 GB, the same figure the ec2 script cost comments use.
A5: Data volume used data (GB) | C5: 0 | D5: New 1 GiB data volumes are empty, so their snapshots and backups are ~0 GB. Set to what you write.
A6: Data in each S3 bucket (GB) | C6: 1 | D6: The buckets are created empty ($0). The S3 scripts quote their costs per 1 GB of data.
A8: A. EC2 folders (ec2/)
A9: Folder | B9: What it creates | C9: Instance as deployed | D9: Public IPv4 | E9: EBS gp3 (GiB) | F9: Snapshots kept (GB) | G9: Primary vault (GB) | H9: DR vault (GB) | I9: Copied cross-region (GB) | J9: Per hour as deployed (USD) | K9: Per day (USD) | L9: Per month (USD) | M9: One-time, first copy (USD) | N9: Per hour, running (USD) | O9: Per hour, stopped (USD) | P9: Note
A10: ec2-01 | B10: Instance + 8 GiB root. No protection | C10: Running | D10: Yes | E10: 8 | F10: 0 | G10: 0 | H10: 0 | I10: 0 | J10: =IF(C10="Running",N10,O10) -> 0.016276712 | K10: =J10*24 -> 0.3906411 | L10: =J10*Rates!$B$4 -> 11.882 | M10: =I10*Rates!$B$22 -> 0 | N10: ='EC2 and EBS'!$D$6+IF(D10="Yes",Rates!$B$27,0)+O10 -> 0.016276712 | O10: =(E10*Rates!$B$16+F10*Rates!$B$17+(G10+H10)*Rates!$B$20)/Rates!$B$4 -> 0.00087671233 | P10: Its generated backup file was removed, so no vaults or backups.
A11: ec2-02 | B11: Instance + encrypted 1 GiB data volume | C11: Running | D11: Yes | E11: 9 | F11: 0 | G11: 0 | H11: 0 | I11: 0 | J11: =IF(C11="Running",N11,O11) -> 0.016386301 | K11: =J11*24 -> 0.39327123 | L11: =J11*Rates!$B$4 -> 11.962 | M11: =I11*Rates!$B$22 -> 0 | N11: ='EC2 and EBS'!$D$6+IF(D11="Yes",Rates!$B$27,0)+O11 -> 0.016386301 | O11: =(E11*Rates!$B$16+F11*Rates!$B$17+(G11+H11)*Rates!$B$20)/Rates!$B$4 -> 0.00098630137
A12: ec2-03 | B12: + data volume + 1 EBS snapshot | C12: Running | D12: Yes | E12: 9 | F12: =$C$5 -> 0 | G12: 0 | H12: 0 | I12: 0 | J12: =IF(C12="Running",N12,O12) -> 0.016386301 | K12: =J12*24 -> 0.39327123 | L12: =J12*Rates!$B$4 -> 11.962 | M12: =I12*Rates!$B$22 -> 0 | N12: ='EC2 and EBS'!$D$6+IF(D12="Yes",Rates!$B$27,0)+O12 -> 0.016386301 | O12: =(E12*Rates!$B$16+F12*Rates!$B$17+(G12+H12)*Rates!$B$20)/Rates!$B$4 -> 0.00098630137 | P12: Snapshot of the data volume (~0 GB while it is empty).
A13: ec2-04 | B13: + data volume + snapshot + AMI | C13: Running | D13: Yes | E13: 9 | F13: =$C$5+$C$4+$C$5 -> 1 | G13: 0 | H13: 0 | I13: 0 | J13: =IF(C13="Running",N13,O13) -> 0.016454795 | K13: =J13*24 -> 0.39491507 | L13: =J13*Rates!$B$4 -> 12.012 | M13: =I13*Rates!$B$22 -> 0 | N13: ='EC2 and EBS'!$D$6+IF(D13="Yes",Rates!$B$27,0)+O13 -> 0.016454795 | O13: =(E13*Rates!$B$16+F13*Rates!$B$17+(G13+H13)*Rates!$B$20)/Rates!$B$4 -> 0.0010547945 | P13: Data snapshot + the AMI's root and data snapshots.
A14: ec2-05 | B14: + data volume + DLM (24 h, keep 1) | C14: Running | D14: Yes | E14: 9 | F14: =$C$4+$C$5 -> 1 | G14: 0 | H14: 0 | I14: 0 | J14: =IF(C14="Running",N14,O14) -> 0.016454795 | K14: =J14*24 -> 0.39491507 | L14: =J14*Rates!$B$4 -> 12.012 | M14: =I14*Rates!$B$22 -> 0 | N14: ='EC2 and EBS'!$D$6+IF(D14="Yes",Rates!$B$27,0)+O14 -> 0.016454795 | O14: =(E14*Rates!$B$16+F14*Rates!$B$17+(G14+H14)*Rates!$B$20)/Rates!$B$4 -> 0.0010547945 | P14: DLM snapshots root + data volume (both tagged DlmTaken). DLM itself is free.
A15: ec2-06 | B15: Instance backup, 1 vault, no copy, no lock | C15: Running | D15: Yes | E15: 8 | F15: 0 | G15: =$C$4 -> 1 | H15: 0 | I15: 0 | J15: =IF(C15="Running",N15,O15) -> 0.016345205 | K15: =J15*24 -> 0.39228493 | L15: =J15*Rates!$B$4 -> 11.932 | M15: =I15*Rates!$B$22 -> 0 | N15: ='EC2 and EBS'!$D$6+IF(D15="Yes",Rates!$B$27,0)+O15 -> 0.016345205 | O15: =(E15*Rates!$B$16+F15*Rates!$B$17+(G15+H15)*Rates!$B$20)/Rates!$B$4 -> 0.00094520548 | P15: Daily 03:00 UTC, kept 1 day. On-demand backup: run the commands from terraform output (not at apply).
A16: ec2-07 | B16: Instance backup + copy to DR vault (DR locked) | C16: Running | D16: Yes | E16: 8 | F16: 0 | G16: =$C$4 -> 1 | H16: =$C$4 -> 1 | I16: =$C$4 -> 1 | J16: =IF(C16="Running",N16,O16) -> 0.016413699 | K16: =J16*24 -> 0.39392877 | L16: =J16*Rates!$B$4 -> 11.982 | M16: =I16*Rates!$B$22 -> 0.02 | N16: ='EC2 and EBS'!$D$6+IF(D16="Yes",Rates!$B$27,0)+O16 -> 0.016413699 | O16: =(E16*Rates!$B$16+F16*Rates!$B$17+(G16+H16)*Rates!$B$20)/Rates!$B$4 -> 0.0010136986 | P16: 1 on-demand backup + 1 copy at apply, daily after, kept 1 day.
A17: ec2-08 | B17: Instance backup + copy to DR vault (DR locked) | C17: Running | D17: No | E17: 8 | F17: 0 | G17: =$C$4 -> 1 | H17: =$C$4 -> 1 | I17: =$C$4 -> 1 | J17: =IF(C17="Running",N17,O17) -> 0.011413699 | K17: =J17*24 -> 0.27392877 | L17: =J17*Rates!$B$4 -> 8.332 | M17: =I17*Rates!$B$22 -> 0.02 | N17: ='EC2 and EBS'!$D$6+IF(D17="Yes",Rates!$B$27,0)+O17 -> 0.011413699 | O17: =(E17*Rates!$B$16+F17*Rates!$B$17+(G17+H17)*Rates!$B$20)/Rates!$B$4 -> 0.0010136986 | P17: Daily backup + copy, kept 7 days. On-demand backup + copy: run the commands from terraform output (not at apply).
A18: ec2-09 | B18: Data-volume backup + copy to DR vault (DR locked) | C18: Running | D18: No | E18: 9 | F18: 0 | G18: =$C$5 -> 0 | H18: =$C$5 -> 0 | I18: =$C$5 -> 0 | J18: =IF(C18="Running",N18,O18) -> 0.011386301 | K18: =J18*24 -> 0.27327123 | L18: =J18*Rates!$B$4 -> 8.312 | M18: =I18*Rates!$B$22 -> 0 | N18: ='EC2 and EBS'!$D$6+IF(D18="Yes",Rates!$B$27,0)+O18 -> 0.011386301 | O18: =(E18*Rates!$B$16+F18*Rates!$B$17+(G18+H18)*Rates!$B$20)/Rates!$B$4 -> 0.00098630137 | P18: Only the data volume is backed up. ~$0 while it is empty.
A19: ec2-backup-dr | B19: Instance + data volume backup + copy to DR (DR locked) | C19: Running | D19: No | E19: 9 | F19: 0 | G19: =$C$4+$C$5 -> 1 | H19: =$C$4+$C$5 -> 1 | I19: =$C$4+$C$5 -> 1 | J19: =IF(C19="Running",N19,O19) -> 0.011523288 | K19: =J19*24 -> 0.2765589 | L19: =J19*Rates!$B$4 -> 8.412 | M19: =I19*Rates!$B$22 -> 0.02 | N19: ='EC2 and EBS'!$D$6+IF(D19="Yes",Rates!$B$27,0)+O19 -> 0.011523288 | O19: =(E19*Rates!$B$16+F19*Rates!$B$17+(G19+H19)*Rates!$B$20)/Rates!$B$4 -> 0.0011232877 | P19: Daily backup + copy, kept 7 days. On-demand backup + copy: run the commands from terraform output (not at apply).
A20: All 10 EC2 folders deployed at once | J20: =SUM(J10:J19) -> 0.1490411 | K20: =SUM(K10:K19) -> 3.5769863 | L20: =SUM(L10:L19) -> 108.8 | M20: =SUM(M10:M19) -> 0.06
A22: B. S3 AWS Backup folders (s3/)
A23: Folder | B23: What it creates | C23: Bucket data (GB) | E23: S3 Standard (GB) | G23: Primary vault (GB) | H23: DR vault (GB) | I23: Copied cross-region (GB) | J23: Per hour (USD) | K23: Per day (USD) | L23: Per month (USD) | M23: One-time, first copy (USD) | P23: Note
A24: s3-05 | B24: Versioned bucket + AWS Backup, 1 vault, no copy | C24: =$C$6 -> 1 | E24: =C24 -> 1 | G24: =MAX(C24,Rates!$B$24/Rates!$B$5) -> 1 | H24: 0 | I24: 0 | J24: =L24/Rates!$B$4 -> 0.0001 | K24: =J24*24 -> 0.0024 | L24: =E24*Rates!$B$10+(G24+H24)*Rates!$B$20 -> 0.073 | M24: =I24*Rates!$B$23 -> 0 | P24: Daily 05:00 UTC, kept 7 days.
A25: s3-06 | B25: Bucket + AWS Backup + copy to DR vault (no lock) | C25: =$C$6 -> 1 | E25: =C25 -> 1 | G25: =MAX(C25,Rates!$B$24/Rates!$B$5) -> 1 | H25: =G25 -> 1 | I25: =C25 -> 1 | J25: =L25/Rates!$B$4 -> 0.00016849315 | K25: =J25*24 -> 0.0040438356 | L25: =E25*Rates!$B$10+(G25+H25)*Rates!$B$20 -> 0.123 | M25: =I25*Rates!$B$23 -> 0.02 | P25: Weekly (Sunday), kept 14 days.
A26: s3-backup-dr | B26: Bucket + AWS Backup + copy to DR (DR locked) | C26: =$C$6 -> 1 | E26: =C26 -> 1 | G26: =MAX(C26,Rates!$B$24/Rates!$B$5) -> 1 | H26: =G26 -> 1 | I26: =C26 -> 1 | J26: =L26/Rates!$B$4 -> 0.00016849315 | K26: =J26*24 -> 0.0040438356 | L26: =E26*Rates!$B$10+(G26+H26)*Rates!$B$20 -> 0.123 | M26: =I26*Rates!$B$23 -> 0.02 | P26: Daily, kept 7 days, compliance lock. Deployed.
A27: All 3 S3 backup folders | J27: =SUM(J24:J26) -> 0.0004369863 | K27: =SUM(K24:K26) -> 0.010487671 | L27: =SUM(L24:L26) -> 0.319 | M27: =SUM(M24:M26) -> 0.04
A29: Not in table B: the other s3/ folders hold only buckets, versioning, lifecycle rules, Object Lock or replication. An empty bucket is $0; their cost per GB is on the S3 and S3 CRR sheets. S3 backup jobs also make LIST/GET requests and the restore rate is $0.02/GB (Rates sheet): fractions of a cent for these buckets. Change C4:C6 or any Instance / Public IPv4 cell to see the effect.

Sheet Rates
A1: Rates and assumptions
A2: us-east-1 (N. Virginia) list prices, checked 2026-10-13, updated 2026-10-26 to match the Terraform scripts. All values in USD. Blue cells on a yellow fill are inputs: edit one and every sheet recalculates. Black = formula, green = link from another sheet.
A4: Hours in a billing month | B4: 730 | C4: AWS divides a month into 730 hours (8,760 / 12). Day = hour x 24.
A5: KB in 1 GB | B5: 1048576 | C5: Binary units: 1 GB = 1,024 MB = 1,048,576 KB.
A6: MB in 1 GB | B6: 1024
A9: Item | B9: Rate | C9: Unit | D9: Status | E9: Source / note
A10: S3 Standard storage (first 50 TB) | B10: 0.023 | C10: $ per GB-month | D10: Published S3 list price | E10: Billed on actual bytes. Standard has no 128 KB minimum object size (that applies to Standard-IA and to AWS Backup).
A11: S3 PUT / COPY / POST / LIST requests | B11: 0.005 | C11: $ per 1,000 requests | D11: Published S3 list price | E11: Replication also makes one PUT per object in the destination. An AWS Backup S3 restore writes each object back with a PUT.
A12: S3 GET requests | B12: 0.0004 | C12: $ per 1,000 requests | D12: AWS S3 pricing page | E12: Replication and AWS Backup read the source object with a GET. AWS Backup's example uses the same $0.004 per 10,000.
A13: Inter-region data transfer (S3 CRR from us-east-1) | B13: 0.02 | C13: $ per GB | D13: Standard inter-region rate | E13: Priced by the SOURCE region. Same-region replication has no transfer charge.
A14: S3 Batch Operations job (used for Batch Replication) | B14: 0.25 | C14: $ per job | D14: AWS S3 pricing page | E14: One fee per job, however many objects.
A15: S3 Batch Operations objects processed | B15: 1 | C15: $ per million objects | D15: AWS S3 pricing page
A16: EBS gp3 volume | B16: 0.08 | C16: $ per GB-month | D16: AWS EBS pricing page | E16: Billed on provisioned size, whether the instance runs or not. gp3 minimum size is 1 GiB.
A17: EBS snapshot, standard tier | B17: 0.05 | C17: $ per GB-month | D17: AWS EBS pricing page | E17: Billed on USED blocks only. First snapshot is a full copy of used blocks; later ones store only changes. Also the rate for AMI backing snapshots and DLM snapshots.
A18: EBS snapshot, archive tier | B18: 0.0125 | C18: $ per GB-month | D18: AWS EBS pricing page | E18: 90-day minimum. Full copy, not incremental. Not used by the stacks.
A19: EBS snapshot archive retrieval | B19: 0.03 | C19: $ per GB, one time | D19: AWS EBS pricing page | E19: Not used by the stacks.
A20: AWS Backup warm storage (EBS, EC2, S3) | B20: 0.05 | C20: $ per GB-month | D20: AWS Backup pricing page (worked examples) | E20: Same $0.05 for EBS, EC2 (AMI + snapshots) and S3, in the primary vault and again in the DR vault. No fee per backup job or copy job.
A21: AWS Backup restore, S3 (warm) | B21: 0.02 | C21: $ per GB | D21: AWS Backup pricing page | E21: Plus a PUT per restored object. Restoring EBS / EC2 has no restore charge.
A22: AWS Backup cross-region copy transfer, EBS / EC2 | B22: 0.02 | C22: $ per GB | D22: AWS Backup pricing page | E22: EBS rate is in the AWS worked example. EC2 backups are EBS snapshots, so the same rate applies. Charged once per copy for the data sent; later copies send only changed blocks.
A23: AWS Backup cross-region copy transfer, S3 | B23: 0.02 | C23: $ per GB | D23: NOT CONFIRMED - check | E23: Set to $0.02 to match the Terraform scripts and the standard us-east-1 inter-region rate (was $0.03, a third-party estimate). The AWS Backup pricing page gives no S3-specific rate. Check the AWS Pricing Calculator and edit this cell.
A24: AWS Backup S3 minimum billed object size | B24: 128 | C24: KB per object | D24: AWS Backup pricing page | E24: An S3 object under 128 KB is billed as 128 KB in a backup.
A25: AWS Backup S3 backup: LIST requests | B25: 0.005 | C25: $ per 1,000 requests | D25: AWS Backup pricing page (example) | E25: Each S3 backup job lists the bucket ($0.05 per 10,000). Fractions of a cent for these small buckets.
A26: AWS Backup S3: EventBridge events | B26: 1 | C26: $ per million events | D26: AWS Backup pricing page (example) | E26: Listed in AWS's S3 backup example. Fractions of a cent here.
A27: Public IPv4 address (in use) | B27: 0.005 | C27: $ per hour | D27: AWS VPC public IPv4 price | E27: ec2-01 to ec2-07 launch in default-VPC subnets, which auto-assign one: billed while the instance runs, released when it stops. ec2-08, ec2-09 and ec2-backup-dr set associate_public_ip_address = false, so they have none.
A28: Free items in the stacks | B28: 0 | C28: $ | D28: AWS pricing pages | E28: Backup vaults, backup plans, selections, Vault Lock, vault access policies, IAM roles and policies, security groups, DLM policies, AMI registration (its snapshots bill as EBS snapshots), and backup / copy jobs themselves.

Sheet S3
A1: S3 object storage: cost of keeping an object
A2: S3 Standard, us-east-1. Month = size x rate. Hour = month / 730. Day = hour x 24. The bucket itself is free; you pay for stored bytes and for requests.
A4: A. Storage cost per object
A5: Object size | B5: Size (GB) | C5: Rate ($/GB-month) | D5: Per hour (USD) | E5: Per day (USD) | F5: Per month (USD) | G5: Note
A6: 1 KB object | B6: =1/Rates!$B$5 -> 9.5367432e-07 | C6: =Rates!$B$10 -> 0.023 | D6: =F6/Rates!$B$4 -> 3.0047273e-11 | E6: =D6*24 -> 7.2113455e-10 | F6: =B6*C6 -> 2.1934509e-08 | G6: Smallest case. Storage is almost free; the PUT request costs far more (see below).
A7: 125.2 KB object (your test file) | B7: =125.2/Rates!$B$5 -> 0.00011940002 | C7: =Rates!$B$10 -> 0.023 | D7: =F7/Rates!$B$4 -> 3.7619186e-09 | E7: =D7*24 -> 9.0286046e-08 | F7: =B7*C7 -> 2.7462006e-06 | G7: The file you uploaded for the replication test.
A8: 1 MB object | B8: =1/Rates!$B$6 -> 0.0009765625 | C8: =Rates!$B$10 -> 0.023 | D8: =F8/Rates!$B$4 -> 3.0768408e-08 | E8: =D8*24 -> 7.3844178e-07 | F8: =B8*C8 -> 2.2460937e-05
A9: 1 GB object | B9: 1 | C9: =Rates!$B$10 -> 0.023 | D9: =F9/Rates!$B$4 -> 3.1506849e-05 | E9: =D9*24 -> 0.00075616438 | F9: =B9*C9 -> 0.023 | G9: Reference size: this row IS the per-GB rate. The S3 scripts quote costs per 1 GB.
A11: B. Request cost (one time, not per hour)
A12: Request | B12: Count | C12: Rate ($ per 1,000) | D12: Cost (USD) | G12: Note
A13: 1 PUT (upload one object) | B13: 1 | C13: =Rates!$B$11 -> 0.005 | D13: =B13/1000*C13 -> 5e-06 | G13: Charged once per upload, whatever the object size.
A14: 1 GET (read one object) | B14: 1 | C14: =Rates!$B$12 -> 0.0004 | D14: =B14/1000*C14 -> 4e-07
A15: 1,000 PUTs | B15: 1000 | C15: =Rates!$B$11 -> 0.005 | D15: =B15/1000*C15 -> 0.005
A16: 1,000,000 PUTs | B16: 1000000 | C16: =Rates!$B$11 -> 0.005 | D16: =B16/1000*C16 -> 5 | G16: Millions of tiny objects cost more in requests than in storage.
A18: One PUT costs this many months of storing a 1 KB object: | D18: =D13/F6 -> 227.9513 | E18: times

Sheet EC2 and EBS
A1: EC2 instances, EBS volumes and EBS snapshots
A2: us-east-1, Linux, on-demand. Month = 730 hours. A STOPPED instance costs $0 for compute (and loses its auto-assigned public IPv4), but its EBS volumes and snapshots keep billing.
A4: A. Free-tier eligible instance types (accounts created on or after 15 July 2025)
A5: Instance type | B5: vCPU / memory | C5: Architecture | D5: Per hour (USD) | E5: Per day (USD) | F5: Per month (USD) | G5: Note (hourly price is the blue input cell)
A6: t3.micro | B6: 2 vCPU / 1 GiB | C6: x86 (Intel) | D6: 0.0104 | E6: =D6*24 -> 0.2496 | F6: =D6*Rates!$B$4 -> 7.592 | G6: Cheapest x86. The type used in every Terraform stack. Also free-tier eligible for pre-July-2025 accounts.
A7: t3.small | B7: 2 vCPU / 2 GiB | C7: x86 (Intel) | D7: 0.0208 | E7: =D7*24 -> 0.4992 | F7: =D7*Rates!$B$4 -> 15.184 | G7: Double the memory of t3.micro at double the price.
A8: t4g.micro | B8: 2 vCPU / 1 GiB | C8: Arm (Graviton) | D8: 0.0084 | E8: =D8*24 -> 0.2016 | F8: =D8*Rates!$B$4 -> 6.132 | G8: Cheapest of the four. Needs an Arm64 AMI, so scripts that look up an x86_64 AMI will not launch it.
A9: t4g.small | B9: 2 vCPU / 2 GiB | C9: Arm (Graviton) | D9: 0.0168 | E9: =D9*24 -> 0.4032 | F9: =D9*Rates!$B$4 -> 12.264 | G9: Needs an Arm64 AMI.
A10: Free-tier rule (AWS EC2 docs): accounts created on or after 15 Jul 2025 can run t3.micro, t3.small, t4g.micro, t4g.small, c7i-flex.large and m7i-flex.large using the $100-$200 credit, for up to 6 months. Accounts created before that date get t2.micro and t3.micro, 750 hours/month for 12 months. To list yours: aws ec2 describe-instance-types --filters Name=free-tier-eligible,Values=true
A11: Stopped instance (any type) | D11: 0 | E11: =D11*24 -> 0 | F11: =D11*Rates!$B$4 -> 0 | G11: Compute stops billing; attached EBS volumes do not.
A12: Public IPv4 address (auto-assigned, while running) | D12: =Rates!$B$27 -> 0.005 | E12: =D12*24 -> 0.12 | F12: =D12*Rates!$B$4 -> 3.65 | G12: ec2-01 to ec2-07 get one from the default VPC. Released (and no longer billed) when the instance stops. ec2-08, ec2-09 and ec2-backup-dr assign none.
A14: B. EBS volume with the minimum configuration (gp3)
A15: Volume | B15: Size (GiB) | C15: Rate ($/GB-month) | D15: Per hour (USD) | E15: Per day (USD) | F15: Per month (USD) | G15: Note
A16: gp3, 1 GiB (smallest allowed) | B16: 1 | C16: =Rates!$B$16 -> 0.08 | D16: =F16/Rates!$B$4 -> 0.00010958904 | E16: =D16*24 -> 0.002630137 | F16: =B16*C16 -> 0.08 | G16: The data volume in ec2-02 to ec2-05, ec2-09 and ec2-backup-dr.
A17: gp3, 8 GiB (Amazon Linux 2023 root minimum) | B17: 8 | C17: =Rates!$B$16 -> 0.08 | D17: =F17/Rates!$B$4 -> 0.00087671233 | E17: =D17*24 -> 0.021041096 | F17: =B17*C17 -> 0.64 | G17: The root volume in every EC2 stack.
A19: Hours the snapshot is kept (edit): | B19: 24
A20: C. EBS snapshot (billed on used blocks, not on volume size)
A21: Snapshot | B21: Used data (GB) | C21: Rate ($/GB-month) | D21: Per hour (USD) | E21: Per day (USD) | F21: Per month (USD) | G21: Note | H21: ="Cost if kept "&$B$19&" hours (USD)" -> Cost if kept 24 hours (USD)
A22: Snapshot, 1 GB used | B22: 1 | C22: =Rates!$B$17 -> 0.05 | D22: =F22/Rates!$B$4 -> 6.8493151e-05 | E22: =D22*24 -> 0.0016438356 | F22: =B22*C22 -> 0.05 | G22: Fresh instance with almost nothing on the disk. | H22: =D22*$B$19 -> 0.0016438356
A23: Snapshot, 1 GB used (root volume, used in all totals) | B23: 1 | C23: =Rates!$B$17 -> 0.05 | D23: =F23/Rates!$B$4 -> 6.8493151e-05 | E23: =D23*24 -> 0.0016438356 | F23: =B23*C23 -> 0.05 | G23: Root-volume snapshot size used on every sheet. | H23: =D23*$B$19 -> 0.0016438356
A24: Snapshot, 8 GB used (full 8 GiB volume) | B24: 8 | C24: =Rates!$B$17 -> 0.05 | D24: =F24/Rates!$B$4 -> 0.00054794521 | E24: =D24*24 -> 0.013150685 | F24: =B24*C24 -> 0.4 | G24: Worst case for an 8 GiB disk: every block in use. | H24: =D24*$B$19 -> 0.013150685
A25: Snapshot billing: there is no fee to create one. The first snapshot copies every used block; each later snapshot stores only blocks that changed. Deleting a snapshot frees only the blocks no later snapshot needs, so deleting early saves little.
A27: D. Whole stack: one t3.micro + public IPv4 + 8 GiB root volume + one 1 GB snapshot
A28: Component | D28: Per hour (USD) | E28: Per day (USD) | F28: Per month (USD) | G28: Note
A29: t3.micro, running | D29: =D6 -> 0.0104 | E29: =D29*24 -> 0.2496 | F29: =F6 -> 7.592 | G29: Compute
A30: Public IPv4 (auto-assigned) | D30: =D12 -> 0.005 | E30: =D30*24 -> 0.12 | F30: =F12 -> 3.65 | G30: Only while running; ec2-08, ec2-09, ec2-backup-dr have none
A31: 8 GiB gp3 root volume | D31: =D17 -> 0.00087671233 | E31: =D31*24 -> 0.021041096 | F31: =F17 -> 0.64 | G31: Billed running or stopped
A32: 1 GB snapshot | D32: =D23 -> 6.8493151e-05 | E32: =D32*24 -> 0.0016438356 | F32: =F23 -> 0.05 | G32: Standard tier
A33: Total, instance running | D33: =SUM(D29:D32) -> 0.016345205 | E33: =SUM(E29:E32) -> 0.39228493 | F33: =SUM(F29:F32) -> 11.932
A34: Total, instance stopped | D34: =SUM(D31:D32) -> 0.00094520548 | E34: =SUM(E31:E32) -> 0.022684932 | F34: =SUM(F31:F32) -> 0.69 | G34: Compute and public IPv4 removed; volume and snapshot remain.

Sheet AWS Backup
A1: AWS Backup: backup job, copy job and restore
A2: AWS Backup charges NO fee per backup job or copy job. You pay for the storage the recovery point occupies, for data leaving a region on a copy, and for the storage the copy occupies at the destination.
A4: A. Backup storage: what one recovery point costs to keep in the vault
A5: Backed-up item | B5: Billed size (GB) | C5: Rate ($/GB-month) | D5: Per hour (USD) | E5: Per day (USD) | F5: Per month (USD) | G5: Note
A6: S3 object, 1 KB (billed as 128 KB) | B6: =MAX(1/Rates!$B$5,Rates!$B$24/Rates!$B$5) -> 0.00012207031 | C6: =Rates!$B$20 -> 0.05 | D6: =F6/Rates!$B$4 -> 8.3609803e-09 | E6: =D6*24 -> 2.0066353e-07 | F6: =B6*C6 -> 6.1035156e-06 | G6: AWS Backup bills any S3 object under 128 KB as 128 KB: 128x what the object really weighs.
A7: S3 object, 1 MB | B7: =MAX(1/Rates!$B$6,Rates!$B$24/Rates!$B$5) -> 0.0009765625 | C7: =Rates!$B$20 -> 0.05 | D7: =F7/Rates!$B$4 -> 6.6887842e-08 | E7: =D7*24 -> 1.6053082e-06 | F7: =B7*C7 -> 4.8828125e-05
A8: S3 object, 1 GB | B8: =MAX(1,Rates!$B$24/Rates!$B$5) -> 1 | C8: =Rates!$B$20 -> 0.05 | D8: =F8/Rates!$B$4 -> 6.8493151e-05 | E8: =D8*24 -> 0.0016438356 | F8: =B8*C8 -> 0.05 | G8: What the S3 backup scripts quote (per 1 GB of bucket data).
A9: EC2 instance backup, 1 GB used | B9: 1 | C9: =Rates!$B$20 -> 0.05 | D9: =F9/Rates!$B$4 -> 6.8493151e-05 | E9: =D9*24 -> 0.0016438356 | F9: =B9*C9 -> 0.05 | G9: Instance config + root volume snapshot, billed on used blocks. ec2-06, ec2-07, ec2-08.
A10: EC2 instance backup, 8 GB used (full 8 GiB root) | B10: 8 | C10: =Rates!$B$20 -> 0.05 | D10: =F10/Rates!$B$4 -> 0.00054794521 | E10: =D10*24 -> 0.013150685 | F10: =B10*C10 -> 0.4 | G10: Worst case.
A11: EBS data volume backup, new and empty (ec2-09) | B11: 0 | C11: =Rates!$B$20 -> 0.05 | D11: =F11/Rates!$B$4 -> 0 | E11: =D11*24 -> 0 | F11: =B11*C11 -> 0 | G11: A new 1 GiB volume has no used blocks, so its snapshot is ~0 GB until you write data.
A13: B. Copy job to a second region: one-time transfer, then storage in the destination vault
A14: Copied item | B14: Data transferred (GB) | C14: Stored at destination (GB) | D14: Transfer rate ($/GB) | E14: Transfer, once (USD) | F14: Destination storage per hour (USD) | G14: per day (USD) | H14: per month (USD) | I14: First month total (USD) | J14: Note
A15: EC2 instance, 1 GB used | B15: =B9 -> 1 | C15: =B9 -> 1 | D15: =Rates!$B$22 -> 0.02 | E15: =B15*D15 -> 0.02 | F15: =H15/Rates!$B$4 -> 6.8493151e-05 | G15: =F15*24 -> 0.0016438356 | H15: =C15*Rates!$B$20 -> 0.05 | I15: =E15+H15 -> 0.07 | J15: Transfer rate is the EBS / EC2 rate.
A16: EC2 instance, 8 GB used | B16: =B10 -> 8 | C16: =B10 -> 8 | D16: =Rates!$B$22 -> 0.02 | E16: =B16*D16 -> 0.16 | F16: =H16/Rates!$B$4 -> 0.00054794521 | G16: =F16*24 -> 0.013150685 | H16: =C16*Rates!$B$20 -> 0.4 | I16: =E16+H16 -> 0.56
A17: S3 object, 1 KB | B17: =1/Rates!$B$5 -> 9.5367432e-07 | C17: =B6 -> 0.00012207031 | D17: =Rates!$B$23 -> 0.02 | E17: =B17*D17 -> 1.9073486e-08 | F17: =H17/Rates!$B$4 -> 8.3609803e-09 | G17: =F17*24 -> 2.0066353e-07 | H17: =C17*Rates!$B$20 -> 6.1035156e-06 | I17: =E17+H17 -> 6.1225891e-06 | J17: Transfers 1 KB but is STORED (billed) as 128 KB at the destination.
A18: S3 object, 1 MB | B18: =1/Rates!$B$6 -> 0.0009765625 | C18: =B7 -> 0.0009765625 | D18: =Rates!$B$23 -> 0.02 | E18: =B18*D18 -> 1.953125e-05 | F18: =H18/Rates!$B$4 -> 6.6887842e-08 | G18: =F18*24 -> 1.6053082e-06 | H18: =C18*Rates!$B$20 -> 4.8828125e-05 | I18: =E18+H18 -> 6.8359375e-05 | J18: Uses the S3 transfer rate, which is not yet confirmed (see Rates).
A19: S3 object, 1 GB | B19: 1 | C19: =B8 -> 1 | D19: =Rates!$B$23 -> 0.02 | E19: =B19*D19 -> 0.02 | F19: =H19/Rates!$B$4 -> 6.8493151e-05 | G19: =F19*24 -> 0.0016438356 | H19: =C19*Rates!$B$20 -> 0.05 | I19: =E19+H19 -> 0.07
A20: A copy is billed three times: storage of the original (table A), transfer out of the source region (once), and storage of the copy at the destination (monthly). Cancelling a copy job part-way still bills the data already sent. Copies into a Vault-Locked vault must use a retention inside the lock's min/max.
A22: C. Restore
A23: Restore | B23: Data (GB) | C23: Rate ($/GB) | D23: Cost (USD) | E23: Note
A24: S3 restore, 1 GB | B24: 1 | C24: =Rates!$B$21 -> 0.02 | D24: =B24*C24 -> 0.02 | E24: Plus S3 PUT requests for the restored objects ($0.005 per 1,000).
A25: EC2 / EBS restore, any size | B25: 8 | C25: 0 | D25: =B25*C25 -> 0 | E25: No AWS Backup restore charge for EBS snapshots. The restored volume then bills as a normal gp3 volume.
A27: D. Example: one EC2 instance (1 GB used), backed up and copied to a second region
A28: Line | B28: Per month (USD) | C28: Note
A29: Primary vault storage | B29: =F9 -> 0.05
A30: DR vault storage | B30: =H15 -> 0.05
A31: Cross-region transfer (first copy only) | B31: =E15 -> 0.02 | C31: One time. Later daily copies send only changed blocks.
A32: Backup job and copy job fees | B32: 0 | C32: AWS Backup has no per-job fee.
A33: Total, first month | B33: =SUM(B29:B32) -> 0.12

Sheet S3 CRR
A1: S3 Cross-Region Replication (CRR) and Same-Region Replication (SRR)
A2: Replication is an automatic rule on the source bucket. You pay for: the data crossing regions (CRR only), the PUT request that writes each replica, the GET that reads the source, and the storage the replica occupies. The rule itself is free. Source-bucket storage is billed as normal and is not repeated here.
A4: A. One-time cost to replicate one object
A5: Object size | B5: Size (GB) | C5: Inter-region transfer (USD) | D5: Replication PUT (USD) | E5: Source GET (USD) | F5: Total once, CRR (USD) | G5: Total once, SRR (USD) | H5: Note
A6: 1 KB | B6: =1/Rates!$B$5 -> 9.5367432e-07 | C6: =B6*Rates!$B$13 -> 1.9073486e-08 | D6: =Rates!$B$11/1000 -> 5e-06 | E6: =Rates!$B$12/1000 -> 4e-07 | F6: =C6+D6+E6 -> 5.4190735e-06 | G6: =D6+E6 -> 5.4e-06 | H6: Request cost dwarfs transfer cost for tiny objects.
A7: 125.2 KB (your test file) | B7: =125.2/Rates!$B$5 -> 0.00011940002 | C7: =B7*Rates!$B$13 -> 2.3880005e-06 | D7: =Rates!$B$11/1000 -> 5e-06 | E7: =Rates!$B$12/1000 -> 4e-07 | F7: =C7+D7+E7 -> 7.7880005e-06 | G7: =D7+E7 -> 5.4e-06
A8: 1 MB | B8: =1/Rates!$B$6 -> 0.0009765625 | C8: =B8*Rates!$B$13 -> 1.953125e-05 | D8: =Rates!$B$11/1000 -> 5e-06 | E8: =Rates!$B$12/1000 -> 4e-07 | F8: =C8+D8+E8 -> 2.493125e-05 | G8: =D8+E8 -> 5.4e-06
A9: 1 GB | B9: 1 | C9: =B9*Rates!$B$13 -> 0.02 | D9: =Rates!$B$11/1000 -> 5e-06 | E9: =Rates!$B$12/1000 -> 4e-07 | F9: =C9+D9+E9 -> 0.0200054 | G9: =D9+E9 -> 5.4e-06 | H9: Transfer dominates for large objects.
A10: SRR (replicating into a bucket in the SAME region) has no inter-region transfer charge, so it costs only the two request fees plus replica storage.
A12: B. Ongoing cost: the replica sitting in the destination bucket
A13: Object size | B13: Size (GB) | C13: Rate ($/GB-month) | D13: Per hour (USD) | E13: Per day (USD) | F13: Per month (USD) | H13: Note
A14: 1 KB | B14: =B6 -> 9.5367432e-07 | C14: =Rates!$B$10 -> 0.023 | D14: =F14/Rates!$B$4 -> 3.0047273e-11 | E14: =D14*24 -> 7.2113455e-10 | F14: =B14*C14 -> 2.1934509e-08
A15: 125.2 KB (your test file) | B15: =B7 -> 0.00011940002 | C15: =Rates!$B$10 -> 0.023 | D15: =F15/Rates!$B$4 -> 3.7619186e-09 | E15: =D15*24 -> 9.0286046e-08 | F15: =B15*C15 -> 2.7462006e-06
A16: 1 MB | B16: =B8 -> 0.0009765625 | C16: =Rates!$B$10 -> 0.023 | D16: =F16/Rates!$B$4 -> 3.0768408e-08 | E16: =D16*24 -> 7.3844178e-07 | F16: =B16*C16 -> 2.2460937e-05
A17: 1 GB | B17: =B9 -> 1 | C17: =Rates!$B$10 -> 0.023 | D17: =F17/Rates!$B$4 -> 3.1506849e-05 | E17: =D17*24 -> 0.00075616438 | F17: =B17*C17 -> 0.023
A18: Same rate for CRR and SRR: the replica is ordinary S3 Standard storage. Replicas keep every version, so a versioned source that overwrites often grows the replica too.
A20: C. Replicating objects that already existed (S3 Batch Replication job)
A21: Scenario | B21: Objects | C21: Job fee (USD) | D21: Per-object fee (USD) | E21: Job total (USD) | F21: Note
A22: Your test: 1 existing object | B22: 1 | C22: =Rates!$B$14 -> 0.25 | D22: =B22/1000000*Rates!$B$15 -> 1e-06 | E22: =C22+D22 -> 0.250001 | F22: The $0.25 job fee is the whole cost.
A23: 1,000 existing objects | B23: 1000 | C23: =Rates!$B$14 -> 0.25 | D23: =B23/1000000*Rates!$B$15 -> 0.001 | E23: =C23+D23 -> 0.251
A24: 1,000,000 existing objects | B24: 1000000 | C24: =Rates!$B$14 -> 0.25 | D24: =B24/1000000*Rates!$B$15 -> 1 | E24: =C24+D24 -> 1.25 | F24: The per-object fee finally matters at this scale.
A25: The Batch job fee is on top of the table A costs, which are paid for every object the job copies. Objects uploaded AFTER the rule exists replicate with no job and no job fee.
